<?xml version='1.0' encoding='utf-8'?>
<robot name="fr3_xhand">

  <material name="fr3_white">
    <color rgba="1.0 1.0 1.0 1.0" />
  </material>

  
  <link name="fr3_link0">
    <visual>
      <geometry>
        <mesh filename="../fr3/meshes/visual/link0.stl" />
      </geometry>
      <material name="fr3_white" />
    </visual>
    <collision>
      <geometry>
        <mesh filename="../fr3/meshes/collision/link0.stl" />
      </geometry>
    </collision>
    <inertial>
      <origin rpy="0 0 0" xyz="-0.041018 -0.00014 0.049974" />
      <mass value="0.629769" />
      <inertia ixx="0.00315" ixy="8.2904e-7" ixz="0.00015" iyy="0.00388" iyz="8.2299e-6" izz="0.004285" />
    </inertial>
  </link>

  
  <link name="fr3_link1">
    <visual>
      <geometry>
        <mesh filename="../fr3/meshes/visual/link1.stl" />
      </geometry>
      <material name="fr3_white" />
    </visual>
    <collision>
      <geometry>
        <mesh filename="../fr3/meshes/collision/link1.stl" />
      </geometry>
    </collision>
    <inertial>
      <origin rpy="0 0 0" xyz="0.003875 0.002081 -0.04762" />
      <mass value="4.970684" />
      <inertia ixx="0.70337" ixy="-0.000139" ixz="0.006772" iyy="0.70661" iyz="0.019169" izz="0.009117" />
    </inertial>
  </link>

  <joint name="fr3_joint1" type="revolute">
    <origin rpy="0 0 0" xyz="0 0 0.333" />
    <parent link="fr3_link0" />
    <child link="fr3_link1" />
    <axis xyz="0 0 1" />
    <limit effort="87" lower="-2.7437" upper="2.7437" velocity="2.62" />
    <dynamics damping="0.1" friction="0.0" />
  </joint>

  
  <link name="fr3_link2">
    <visual>
      <geometry>
        <mesh filename="../fr3/meshes/visual/link2.stl" />
      </geometry>
      <material name="fr3_white" />
    </visual>
    <collision>
      <geometry>
        <mesh filename="../fr3/meshes/collision/link2.stl" />
      </geometry>
    </collision>
    <inertial>
      <origin rpy="0 0 0" xyz="-0.003141 -0.02872 0.003495" />
      <mass value="0.646926" />
      <inertia ixx="0.007962" ixy="-0.003925" ixz="0.010254" iyy="0.02811" iyz="0.000704" izz="0.025995" />
    </inertial>
  </link>

  <joint name="fr3_joint2" type="revolute">
    <origin rpy="-1.5707963267948966 0 0" xyz="0 0 0" />
    <parent link="fr3_link1" />
    <child link="fr3_link2" />
    <axis xyz="0 0 1" />
    <limit effort="87" lower="-1.7837" upper="1.7837" velocity="2.62" />
    <dynamics damping="0.1" friction="0.0" />
  </joint>

  
  <link name="fr3_link3">
    <visual>
      <geometry>
        <mesh filename="../fr3/meshes/visual/link3.stl" />
      </geometry>
      <material name="fr3_white" />
    </visual>
    <collision>
      <geometry>
        <mesh filename="../fr3/meshes/collision/link3.stl" />
      </geometry>
    </collision>
    <inertial>
      <origin rpy="0 0 0" xyz="0.027518 0.039252 -0.066502" />
      <mass value="3.228604" />
      <inertia ixx="0.037242" ixy="-0.004761" ixz="-0.011396" iyy="0.036155" iyz="-0.012805" izz="0.01083" />
    </inertial>
  </link>

  <joint name="fr3_joint3" type="revolute">
    <origin rpy="1.5707963267948966 0 0" xyz="0 -0.316 0" />
    <parent link="fr3_link2" />
    <child link="fr3_link3" />
    <axis xyz="0 0 1" />
    <limit effort="87" lower="-2.9007" upper="2.9007" velocity="2.62" />
    <dynamics damping="0.1" friction="0.0" />
  </joint>

  
  <link name="fr3_link4">
    <visual>
      <geometry>
        <mesh filename="../fr3/meshes/visual/link4.stl" />
      </geometry>
      <material name="fr3_white" />
    </visual>
    <collision>
      <geometry>
        <mesh filename="../fr3/meshes/collision/link4.stl" />
      </geometry>
    </collision>
    <inertial>
      <origin rpy="0 0 0" xyz="-0.05317 0.104419 0.027454" />
      <mass value="3.587895" />
      <inertia ixx="0.025853" ixy="0.007796" ixz="-0.001332" iyy="0.019552" iyz="-0.008641" izz="0.028323" />
    </inertial>
  </link>

  <joint name="fr3_joint4" type="revolute">
    <origin rpy="1.5707963267948966 0 0" xyz="0.0825 0 0" />
    <parent link="fr3_link3" />
    <child link="fr3_link4" />
    <axis xyz="0 0 1" />
    <limit effort="87" lower="-3.0421" upper="-0.1518" velocity="2.62" />
    <dynamics damping="0.1" friction="0.0" />
  </joint>

  
  <link name="fr3_link5">
    <visual>
      <geometry>
        <mesh filename="../fr3/meshes/visual/link5.stl" />
      </geometry>
      <material name="fr3_white" />
    </visual>
    <collision>
      <geometry>
        <mesh filename="../fr3/meshes/collision/link5.stl" />
      </geometry>
    </collision>
    <inertial>
      <origin rpy="0 0 0" xyz="-0.011953 0.041065 -0.038437" />
      <mass value="1.225946" />
      <inertia ixx="0.035549" ixy="-0.002117" ixz="-0.004037" iyy="0.029474" iyz="0.000229" izz="0.008627" />
    </inertial>
  </link>

  <joint name="fr3_joint5" type="revolute">
    <origin rpy="-1.5707963267948966 0 0" xyz="-0.0825 0.384 0" />
    <parent link="fr3_link4" />
    <child link="fr3_link5" />
    <axis xyz="0 0 1" />
    <limit effort="12" lower="-2.8065" upper="2.8065" velocity="5.26" />
    <dynamics damping="0.1" friction="0.0" />
  </joint>

  
  <link name="fr3_link6">
    <visual>
      <geometry>
        <mesh filename="../fr3/meshes/visual/link6.stl" />
      </geometry>
      <material name="fr3_white" />
    </visual>
    <collision>
      <geometry>
        <mesh filename="../fr3/meshes/collision/link6.stl" />
      </geometry>
    </collision>
    <inertial>
      <origin rpy="0 0 0" xyz="0.060149 -0.014117 -0.010517" />
      <mass value="1.666555" />
      <inertia ixx="0.001964" ixy="0.000109" ixz="-0.001158" iyy="0.004354" iyz="0.000341" izz="0.005433" />
    </inertial>
  </link>

  <joint name="fr3_joint6" type="revolute">
    <origin rpy="1.5707963267948966 0 0" xyz="0 0 0" />
    <parent link="fr3_link5" />
    <child link="fr3_link6" />
    <axis xyz="0 0 1" />
    <limit effort="12" lower="0.5445" upper="4.5169" velocity="4.18" />
    <dynamics damping="0.1" friction="0.0" />
  </joint>

  
  <link name="fr3_link7">
    <visual>
      <geometry>
        <mesh filename="../fr3/meshes/visual/link7.stl" />
      </geometry>
      <material name="fr3_white" />
    </visual>
    <collision>
      <geometry>
        <mesh filename="../fr3/meshes/collision/link7.stl" />
      </geometry>
    </collision>
    <inertial>
      <origin rpy="0 0 0" xyz="0.010517 -0.004252 0.061597" />
      <mass value="0.735522" />
      <inertia ixx="0.012516" ixy="-0.000428" ixz="-0.001196" iyy="0.010027" iyz="-0.000741" izz="0.004815" />
    </inertial>
  </link>

  <joint name="fr3_joint7" type="revolute">
    <origin rpy="1.5707963267948966 0 0" xyz="0.088 0 0" />
    <parent link="fr3_link6" />
    <child link="fr3_link7" />
    <axis xyz="0 0 1" />
    <limit effort="12" lower="-3.0159" upper="3.0159" velocity="5.26" />
    <dynamics damping="0.1" friction="0.0" />
  </joint>

  
  <link name="fr3_link8" />

  <joint name="fr3_joint8" type="fixed">
    <origin rpy="0 0 0" xyz="0 0 0.107" />
    <parent link="fr3_link7" />
    <child link="fr3_link8" />
  </joint>

<material name="dim_gray">
    <color rgba="0.412 0.412 0.412 1.0" />
  </material>
  <material name="gray">
    <color rgba="0.67 0.67 0.67 1.0" />
  </material>

  
  <link name="palm">
    <visual>
      <origin xyz="0 0 0" rpy="0 0 0" />
      <geometry>
        <mesh filename="../xhand2R32/meshes/right_hand_link_.stl" />
      </geometry>
      <material name="dim_gray" />
    </visual>
    <collision>
      <origin xyz="0 0 0" rpy="0 0 0" />
      <geometry>
        <mesh filename="../xhand2R32/meshes/right_hand_link_.stl" />
      </geometry>
    </collision>
  </link>

  
  <link name="thumb_bend_link">
    <visual>
      <origin xyz="0 0 0" rpy="0 0 0" />
      <geometry>
        <mesh filename="../xhand2R32/meshes/right_hand_thumb_bend_link_.stl" />
      </geometry>
      <material name="gray" />
    </visual>
    <collision>
      <origin xyz="0 0 0" rpy="0 0 0" />
      <geometry>
        <mesh filename="../xhand2R32/meshes/right_hand_thumb_bend_link_.stl" />
      </geometry>
    </collision>
  </link>
  <link name="thumb_rota_link1">
    <visual>
      <origin xyz="0 0 0" rpy="0 0 0" />
      <geometry>
        <mesh filename="../xhand2R32/meshes/right_hand_thumb_rota_link1_.stl" />
      </geometry>
      <material name="gray" />
    </visual>
    <collision>
      <origin xyz="0 0 0" rpy="0 0 0" />
      <geometry>
        <mesh filename="../xhand2R32/meshes/right_hand_thumb_rota_link1_.stl" />
      </geometry>
    </collision>
  </link>
  <link name="thumb_rota_link2">
    <visual>
      <origin xyz="0 0 0" rpy="0 0 0" />
      <geometry>
        <mesh filename="../xhand2R32/meshes/right_hand_thumb_rota_link2_.stl" />
      </geometry>
      <material name="gray" />
    </visual>
    <collision>
      <origin xyz="0 0 0" rpy="0 0 0" />
      <geometry>
        <mesh filename="../xhand2R32/meshes/right_hand_thumb_rota_link2_.stl" />
      </geometry>
    </collision>
  </link>

  <joint name="thumb_joint0" type="revolute">
    <parent link="palm" />
    <child link="thumb_bend_link" />
    <origin xyz="0.0228 -0.0095 0.0305" rpy="0 0 0" />
    <axis xyz="0 0 -1" />
    <limit lower="0.0" upper="1.83" effort="10" velocity="3.14" />
  </joint>
  <joint name="thumb_joint1" type="revolute">
    <parent link="thumb_bend_link" />
    <child link="thumb_rota_link1" />
    <origin xyz="0.028599 0.0083177 0.00178" rpy="0.2618 0 0.0407" />
    <axis xyz="0 -1 0" />
    <limit lower="-1.05" upper="1.57" effort="10" velocity="3.14" />
  </joint>
  <joint name="thumb_joint2" type="revolute">
    <parent link="thumb_rota_link1" />
    <child link="thumb_rota_link2" />
    <origin xyz="0.0553 0 0" rpy="0 0 0" />
    <axis xyz="0 -1 0" />
    <limit lower="-0.175" upper="1.83" effort="10" velocity="3.14" />
  </joint>

  
  <link name="index_bend_link">
    <visual>
      <origin xyz="0 0 0" rpy="0 0 0" />
      <geometry>
        <mesh filename="../xhand2R32/meshes/right_hand_index_bend_link_.stl" />
      </geometry>
      <material name="gray" />
    </visual>
    <collision>
      <origin xyz="0 0 0" rpy="0 0 0" />
      <geometry>
        <mesh filename="../xhand2R32/meshes/right_hand_index_bend_link_.stl" />
      </geometry>
    </collision>
  </link>
  <link name="index_rota_link1">
    <visual>
      <origin xyz="0 0 0" rpy="0 0 0" />
      <geometry>
        <mesh filename="../xhand2R32/meshes/right_hand_index_rota_link1_.stl" />
      </geometry>
      <material name="gray" />
    </visual>
    <collision>
      <origin xyz="0 0 0" rpy="0 0 0" />
      <geometry>
        <mesh filename="../xhand2R32/meshes/right_hand_index_rota_link1_.stl" />
      </geometry>
    </collision>
  </link>
  <link name="index_rota_link2">
    <visual>
      <origin xyz="0 0 0" rpy="0 0 0" />
      <geometry>
        <mesh filename="../xhand2R32/meshes/right_hand_index_rota_link2_.stl" />
      </geometry>
      <material name="gray" />
    </visual>
    <collision>
      <origin xyz="0 0 0" rpy="0 0 0" />
      <geometry>
        <mesh filename="../xhand2R32/meshes/right_hand_index_rota_link2_.stl" />
      </geometry>
    </collision>
  </link>

  <joint name="index_joint0" type="revolute">
    <parent link="palm" />
    <child link="index_bend_link" />
    <origin xyz="0.0265 -0.0065 0.0899" rpy="0 0 0" />
    <axis xyz="0 1 0" />
    <limit lower="-0.175" upper="0.175" effort="10" velocity="3.14" />
  </joint>
  <joint name="index_joint1" type="revolute">
    <parent link="index_bend_link" />
    <child link="index_rota_link1" />
    <origin xyz="0 0 0.0178" rpy="0 0 0" />
    <axis xyz="1 0 0" />
    <limit lower="0.0" upper="1.92" effort="10" velocity="3.14" />
  </joint>
  <joint name="index_joint2" type="revolute">
    <parent link="index_rota_link1" />
    <child link="index_rota_link2" />
    <origin xyz="0 0 0.0558" rpy="0 0 0" />
    <axis xyz="1 0 0" />
    <limit lower="0.0" upper="1.92" effort="10" velocity="3.14" />
  </joint>

  
  <link name="mid_link1">
    <visual>
      <origin xyz="0 0 0" rpy="0 0 0" />
      <geometry>
        <mesh filename="../xhand2R32/meshes/right_hand_mid_link1_.stl" />
      </geometry>
      <material name="gray" />
    </visual>
    <collision>
      <origin xyz="0 0 0" rpy="0 0 0" />
      <geometry>
        <mesh filename="../xhand2R32/meshes/right_hand_mid_link1_.stl" />
      </geometry>
    </collision>
  </link>
  <link name="mid_link2">
    <visual>
      <origin xyz="0 0 0" rpy="0 0 0" />
      <geometry>
        <mesh filename="../xhand2R32/meshes/right_hand_mid_link2_.stl" />
      </geometry>
      <material name="gray" />
    </visual>
    <collision>
      <origin xyz="0 0 0" rpy="0 0 0" />
      <geometry>
        <mesh filename="../xhand2R32/meshes/right_hand_mid_link2_.stl" />
      </geometry>
    </collision>
  </link>

  <joint name="middle_joint0" type="revolute">
    <parent link="palm" />
    <child link="mid_link1" />
    <origin xyz="0.004 -0.0065 0.1082" rpy="0 0 0" />
    <axis xyz="1 0 0" />
    <limit lower="0.0" upper="1.92" effort="10" velocity="3.14" />
  </joint>
  <joint name="middle_joint1" type="revolute">
    <parent link="mid_link1" />
    <child link="mid_link2" />
    <origin xyz="0 0 0.0558" rpy="0 0 0" />
    <axis xyz="1 0 0" />
    <limit lower="0.0" upper="1.92" effort="10" velocity="3.14" />
  </joint>

  
  <link name="ring_link1">
    <visual>
      <origin xyz="0 0 0" rpy="0 0 0" />
      <geometry>
        <mesh filename="../xhand2R32/meshes/right_hand_ring_link1_.stl" />
      </geometry>
      <material name="gray" />
    </visual>
    <collision>
      <origin xyz="0 0 0" rpy="0 0 0" />
      <geometry>
        <mesh filename="../xhand2R32/meshes/right_hand_ring_link1_.stl" />
      </geometry>
    </collision>
  </link>
  <link name="ring_link2">
    <visual>
      <origin xyz="0 0 0" rpy="0 0 0" />
      <geometry>
        <mesh filename="../xhand2R32/meshes/right_hand_ring_link2_.stl" />
      </geometry>
      <material name="gray" />
    </visual>
    <collision>
      <origin xyz="0 0 0" rpy="0 0 0" />
      <geometry>
        <mesh filename="../xhand2R32/meshes/right_hand_ring_link2_.stl" />
      </geometry>
    </collision>
  </link>

  <joint name="ring_joint0" type="revolute">
    <parent link="palm" />
    <child link="ring_link1" />
    <origin xyz="-0.016 -0.0065 0.1052" rpy="0 0 0" />
    <axis xyz="1 0 0" />
    <limit lower="0.0" upper="1.92" effort="10" velocity="3.14" />
  </joint>
  <joint name="ring_joint1" type="revolute">
    <parent link="ring_link1" />
    <child link="ring_link2" />
    <origin xyz="0 0 0.0558" rpy="0 0 0" />
    <axis xyz="1 0 0" />
    <limit lower="0.0" upper="1.92" effort="10" velocity="3.14" />
  </joint>

  
  <link name="pinky_link1">
    <visual>
      <origin xyz="0 0 0" rpy="0 0 0" />
      <geometry>
        <mesh filename="../xhand2R32/meshes/right_hand_pinky_link1_.stl" />
      </geometry>
      <material name="gray" />
    </visual>
    <collision>
      <origin xyz="0 0 0" rpy="0 0 0" />
      <geometry>
        <mesh filename="../xhand2R32/meshes/right_hand_pinky_link1_.stl" />
      </geometry>
    </collision>
  </link>
  <link name="pinky_link2">
    <visual>
      <origin xyz="0 0 0" rpy="0 0 0" />
      <geometry>
        <mesh filename="../xhand2R32/meshes/right_hand_pinky_link2_.stl" />
      </geometry>
      <material name="gray" />
    </visual>
    <collision>
      <origin xyz="0 0 0" rpy="0 0 0" />
      <geometry>
        <mesh filename="../xhand2R32/meshes/right_hand_pinky_link2_.stl" />
      </geometry>
    </collision>
  </link>

  <joint name="pinky_joint0" type="revolute">
    <parent link="palm" />
    <child link="pinky_link1" />
    <origin xyz="-0.036 -0.0065 0.1022" rpy="0 0 0" />
    <axis xyz="1 0 0" />
    <limit lower="0.0" upper="1.92" effort="10" velocity="3.14" />
  </joint>
  <joint name="pinky_joint1" type="revolute">
    <parent link="pinky_link1" />
    <child link="pinky_link2" />
    <origin xyz="0 0 0.0558" rpy="0 0 0" />
    <axis xyz="1 0 0" />
    <limit lower="0.0" upper="1.92" effort="10" velocity="3.14" />
  </joint>

<joint name="hand_mount" type="fixed"><parent link="fr3_link8" /><child link="palm" /><origin xyz="0 0 0" rpy="0 0 3.14159" /></joint></robot>